Traceback (most recent call last):
  File "/Users/Alvin/opt/anaconda3/lib/python3.7/site-packages/jupyter_cache/executors/utils.py", line 56, in single_nb_execution
    record_timing=False,
  File "/Users/Alvin/opt/anaconda3/lib/python3.7/site-packages/nbclient/client.py", line 1082, in execute
    return NotebookClient(nb=nb, resources=resources, km=km, **kwargs).execute()
  File "/Users/Alvin/opt/anaconda3/lib/python3.7/site-packages/nbclient/util.py", line 74, in wrapped
    return just_run(coro(*args, **kwargs))
  File "/Users/Alvin/opt/anaconda3/lib/python3.7/site-packages/nbclient/util.py", line 53, in just_run
    return loop.run_until_complete(coro)
  File "/Users/Alvin/opt/anaconda3/lib/python3.7/asyncio/base_events.py", line 583, in run_until_complete
    return future.result()
  File "/Users/Alvin/opt/anaconda3/lib/python3.7/site-packages/nbclient/client.py", line 536, in async_execute
    cell, index, execution_count=self.code_cells_executed + 1
  File "/Users/Alvin/opt/anaconda3/lib/python3.7/site-packages/nbclient/client.py", line 827, in async_execute_cell
    self._check_raise_for_error(cell, exec_reply)
  File "/Users/Alvin/opt/anaconda3/lib/python3.7/site-packages/nbclient/client.py", line 735, in _check_raise_for_error
    raise CellExecutionError.from_cell_and_msg(cell, exec_reply['content'])
nbclient.exceptions.CellExecutionError: An error occurred while executing the following cell:
------------------
# main()
num_of_index_page = 2
board_name = 'Food'
url = 'https://www.ptt.cc/bbs/{}/index.html'.format(board_name)
all_links =[]
for page in range(1,num_of_index_page):
    all_links = all_links + extractArtLinks(url)
    url = findPrevIndex(url)
len(all_links)
------------------

[0;31m---------------------------------------------------------------------------[0m
[0;31mRemoteDisconnected[0m                        Traceback (most recent call last)
[0;32m~/opt/anaconda3/envs/ckiptagger/lib/python3.6/site-packages/urllib3/connectionpool.py[0m in [0;36murlopen[0;34m(self, method, url, body, headers, retries, redirect, assert_same_host, timeout, pool_timeout, release_conn, chunked, body_pos, **response_kw)[0m
[1;32m    676[0m                 [0mheaders[0m[0;34m=[0m[0mheaders[0m[0;34m,[0m[0;34m[0m[0;34m[0m[0m
[0;32m--> 677[0;31m                 [0mchunked[0m[0;34m=[0m[0mchunked[0m[0;34m,[0m[0;34m[0m[0;34m[0m[0m
[0m[1;32m    678[0m             )

[0;32m~/opt/anaconda3/envs/ckiptagger/lib/python3.6/site-packages/urllib3/connectionpool.py[0m in [0;36m_make_request[0;34m(self, conn, method, url, timeout, chunked, **httplib_request_kw)[0m
[1;32m    425[0m                     [0;31m# Otherwise it looks like a bug in the code.[0m[0;34m[0m[0;34m[0m[0;34m[0m[0m
[0;32m--> 426[0;31m                     [0msix[0m[0;34m.[0m[0mraise_from[0m[0;34m([0m[0me[0m[0;34m,[0m [0;32mNone[0m[0;34m)[0m[0;34m[0m[0;34m[0m[0m
[0m[1;32m    427[0m         [0;32mexcept[0m [0;34m([0m[0mSocketTimeout[0m[0;34m,[0m [0mBaseSSLError[0m[0;34m,[0m [0mSocketError[0m[0;34m)[0m [0;32mas[0m [0me[0m[0;34m:[0m[0;34m[0m[0;34m[0m[0m

[0;32m~/opt/anaconda3/envs/ckiptagger/lib/python3.6/site-packages/urllib3/packages/six.py[0m in [0;36mraise_from[0;34m(value, from_value)[0m

[0;32m~/opt/anaconda3/envs/ckiptagger/lib/python3.6/site-packages/urllib3/connectionpool.py[0m in [0;36m_make_request[0;34m(self, conn, method, url, timeout, chunked, **httplib_request_kw)[0m
[1;32m    420[0m                 [0;32mtry[0m[0;34m:[0m[0;34m[0m[0;34m[0m[0m
[0;32m--> 421[0;31m                     [0mhttplib_response[0m [0;34m=[0m [0mconn[0m[0;34m.[0m[0mgetresponse[0m[0;34m([0m[0;34m)[0m[0;34m[0m[0;34m[0m[0m
[0m[1;32m    422[0m                 [0;32mexcept[0m [0mBaseException[0m [0;32mas[0m [0me[0m[0;34m:[0m[0;34m[0m[0;34m[0m[0m

[0;32m~/opt/anaconda3/envs/ckiptagger/lib/python3.6/http/client.py[0m in [0;36mgetresponse[0;34m(self)[0m
[1;32m   1378[0m             [0;32mtry[0m[0;34m:[0m[0;34m[0m[0;34m[0m[0m
[0;32m-> 1379[0;31m                 [0mresponse[0m[0;34m.[0m[0mbegin[0m[0;34m([0m[0;34m)[0m[0;34m[0m[0;34m[0m[0m
[0m[1;32m   1380[0m             [0;32mexcept[0m [0mConnectionError[0m[0;34m:[0m[0;34m[0m[0;34m[0m[0m

[0;32m~/opt/anaconda3/envs/ckiptagger/lib/python3.6/http/client.py[0m in [0;36mbegin[0;34m(self)[0m
[1;32m    310[0m         [0;32mwhile[0m [0;32mTrue[0m[0;34m:[0m[0;34m[0m[0;34m[0m[0m
[0;32m--> 311[0;31m             [0mversion[0m[0;34m,[0m [0mstatus[0m[0;34m,[0m [0mreason[0m [0;34m=[0m [0mself[0m[0;34m.[0m[0m_read_status[0m[0;34m([0m[0;34m)[0m[0;34m[0m[0;34m[0m[0m
[0m[1;32m    312[0m             [0;32mif[0m [0mstatus[0m [0;34m!=[0m [0mCONTINUE[0m[0;34m:[0m[0;34m[0m[0;34m[0m[0m

[0;32m~/opt/anaconda3/envs/ckiptagger/lib/python3.6/http/client.py[0m in [0;36m_read_status[0;34m(self)[0m
[1;32m    279[0m             [0;31m# sending a valid response.[0m[0;34m[0m[0;34m[0m[0;34m[0m[0m
[0;32m--> 280[0;31m             raise RemoteDisconnected("Remote end closed connection without"
[0m[1;32m    281[0m                                      " response")

[0;31mRemoteDisconnected[0m: Remote end closed connection without response

During handling of the above exception, another exception occurred:

[0;31mProtocolError[0m                             Traceback (most recent call last)
[0;32m~/opt/anaconda3/envs/ckiptagger/lib/python3.6/site-packages/requests/adapters.py[0m in [0;36msend[0;34m(self, request, stream, timeout, verify, cert, proxies)[0m
[1;32m    448[0m                     [0mretries[0m[0;34m=[0m[0mself[0m[0;34m.[0m[0mmax_retries[0m[0;34m,[0m[0;34m[0m[0;34m[0m[0m
[0;32m--> 449[0;31m                     [0mtimeout[0m[0;34m=[0m[0mtimeout[0m[0;34m[0m[0;34m[0m[0m
[0m[1;32m    450[0m                 )

[0;32m~/opt/anaconda3/envs/ckiptagger/lib/python3.6/site-packages/urllib3/connectionpool.py[0m in [0;36murlopen[0;34m(self, method, url, body, headers, retries, redirect, assert_same_host, timeout, pool_timeout, release_conn, chunked, body_pos, **response_kw)[0m
[1;32m    726[0m             retries = retries.increment(
[0;32m--> 727[0;31m                 [0mmethod[0m[0;34m,[0m [0murl[0m[0;34m,[0m [0merror[0m[0;34m=[0m[0me[0m[0;34m,[0m [0m_pool[0m[0;34m=[0m[0mself[0m[0;34m,[0m [0m_stacktrace[0m[0;34m=[0m[0msys[0m[0;34m.[0m[0mexc_info[0m[0;34m([0m[0;34m)[0m[0;34m[[0m[0;36m2[0m[0;34m][0m[0;34m[0m[0;34m[0m[0m
[0m[1;32m    728[0m             )

[0;32m~/opt/anaconda3/envs/ckiptagger/lib/python3.6/site-packages/urllib3/util/retry.py[0m in [0;36mincrement[0;34m(self, method, url, response, error, _pool, _stacktrace)[0m
[1;32m    402[0m             [0;32mif[0m [0mread[0m [0;32mis[0m [0;32mFalse[0m [0;32mor[0m [0;32mnot[0m [0mself[0m[0;34m.[0m[0m_is_method_retryable[0m[0;34m([0m[0mmethod[0m[0;34m)[0m[0;34m:[0m[0;34m[0m[0;34m[0m[0m
[0;32m--> 403[0;31m                 [0;32mraise[0m [0msix[0m[0;34m.[0m[0mreraise[0m[0;34m([0m[0mtype[0m[0;34m([0m[0merror[0m[0;34m)[0m[0;34m,[0m [0merror[0m[0;34m,[0m [0m_stacktrace[0m[0;34m)[0m[0;34m[0m[0;34m[0m[0m
[0m[1;32m    404[0m             [0;32melif[0m [0mread[0m [0;32mis[0m [0;32mnot[0m [0;32mNone[0m[0;34m:[0m[0;34m[0m[0;34m[0m[0m

[0;32m~/opt/anaconda3/envs/ckiptagger/lib/python3.6/site-packages/urllib3/packages/six.py[0m in [0;36mreraise[0;34m(tp, value, tb)[0m
[1;32m    733[0m             [0;32mif[0m [0mvalue[0m[0;34m.[0m[0m__traceback__[0m [0;32mis[0m [0;32mnot[0m [0mtb[0m[0;34m:[0m[0;34m[0m[0;34m[0m[0m
[0;32m--> 734[0;31m                 [0;32mraise[0m [0mvalue[0m[0;34m.[0m[0mwith_traceback[0m[0;34m([0m[0mtb[0m[0;34m)[0m[0;34m[0m[0;34m[0m[0m
[0m[1;32m    735[0m             [0;32mraise[0m [0mvalue[0m[0;34m[0m[0;34m[0m[0m

[0;32m~/opt/anaconda3/envs/ckiptagger/lib/python3.6/site-packages/urllib3/connectionpool.py[0m in [0;36murlopen[0;34m(self, method, url, body, headers, retries, redirect, assert_same_host, timeout, pool_timeout, release_conn, chunked, body_pos, **response_kw)[0m
[1;32m    676[0m                 [0mheaders[0m[0;34m=[0m[0mheaders[0m[0;34m,[0m[0;34m[0m[0;34m[0m[0m
[0;32m--> 677[0;31m                 [0mchunked[0m[0;34m=[0m[0mchunked[0m[0;34m,[0m[0;34m[0m[0;34m[0m[0m
[0m[1;32m    678[0m             )

[0;32m~/opt/anaconda3/envs/ckiptagger/lib/python3.6/site-packages/urllib3/connectionpool.py[0m in [0;36m_make_request[0;34m(self, conn, method, url, timeout, chunked, **httplib_request_kw)[0m
[1;32m    425[0m                     [0;31m# Otherwise it looks like a bug in the code.[0m[0;34m[0m[0;34m[0m[0;34m[0m[0m
[0;32m--> 426[0;31m                     [0msix[0m[0;34m.[0m[0mraise_from[0m[0;34m([0m[0me[0m[0;34m,[0m [0;32mNone[0m[0;34m)[0m[0;34m[0m[0;34m[0m[0m
[0m[1;32m    427[0m         [0;32mexcept[0m [0;34m([0m[0mSocketTimeout[0m[0;34m,[0m [0mBaseSSLError[0m[0;34m,[0m [0mSocketError[0m[0;34m)[0m [0;32mas[0m [0me[0m[0;34m:[0m[0;34m[0m[0;34m[0m[0m

[0;32m~/opt/anaconda3/envs/ckiptagger/lib/python3.6/site-packages/urllib3/packages/six.py[0m in [0;36mraise_from[0;34m(value, from_value)[0m

[0;32m~/opt/anaconda3/envs/ckiptagger/lib/python3.6/site-packages/urllib3/connectionpool.py[0m in [0;36m_make_request[0;34m(self, conn, method, url, timeout, chunked, **httplib_request_kw)[0m
[1;32m    420[0m                 [0;32mtry[0m[0;34m:[0m[0;34m[0m[0;34m[0m[0m
[0;32m--> 421[0;31m                     [0mhttplib_response[0m [0;34m=[0m [0mconn[0m[0;34m.[0m[0mgetresponse[0m[0;34m([0m[0;34m)[0m[0;34m[0m[0;34m[0m[0m
[0m[1;32m    422[0m                 [0;32mexcept[0m [0mBaseException[0m [0;32mas[0m [0me[0m[0;34m:[0m[0;34m[0m[0;34m[0m[0m

[0;32m~/opt/anaconda3/envs/ckiptagger/lib/python3.6/http/client.py[0m in [0;36mgetresponse[0;34m(self)[0m
[1;32m   1378[0m             [0;32mtry[0m[0;34m:[0m[0;34m[0m[0;34m[0m[0m
[0;32m-> 1379[0;31m                 [0mresponse[0m[0;34m.[0m[0mbegin[0m[0;34m([0m[0;34m)[0m[0;34m[0m[0;34m[0m[0m
[0m[1;32m   1380[0m             [0;32mexcept[0m [0mConnectionError[0m[0;34m:[0m[0;34m[0m[0;34m[0m[0m

[0;32m~/opt/anaconda3/envs/ckiptagger/lib/python3.6/http/client.py[0m in [0;36mbegin[0;34m(self)[0m
[1;32m    310[0m         [0;32mwhile[0m [0;32mTrue[0m[0;34m:[0m[0;34m[0m[0;34m[0m[0m
[0;32m--> 311[0;31m             [0mversion[0m[0;34m,[0m [0mstatus[0m[0;34m,[0m [0mreason[0m [0;34m=[0m [0mself[0m[0;34m.[0m[0m_read_status[0m[0;34m([0m[0;34m)[0m[0;34m[0m[0;34m[0m[0m
[0m[1;32m    312[0m             [0;32mif[0m [0mstatus[0m [0;34m!=[0m [0mCONTINUE[0m[0;34m:[0m[0;34m[0m[0;34m[0m[0m

[0;32m~/opt/anaconda3/envs/ckiptagger/lib/python3.6/http/client.py[0m in [0;36m_read_status[0;34m(self)[0m
[1;32m    279[0m             [0;31m# sending a valid response.[0m[0;34m[0m[0;34m[0m[0;34m[0m[0m
[0;32m--> 280[0;31m             raise RemoteDisconnected("Remote end closed connection without"
[0m[1;32m    281[0m                                      " response")

[0;31mProtocolError[0m: ('Connection aborted.', RemoteDisconnected('Remote end closed connection without response',))

During handling of the above exception, another exception occurred:

[0;31mConnectionError[0m                           Traceback (most recent call last)
[0;32m<ipython-input-2-1cf28e3c49be>[0m in [0;36m<module>[0;34m[0m
[1;32m      5[0m [0mall_links[0m [0;34m=[0m[0;34m[[0m[0;34m][0m[0;34m[0m[0;34m[0m[0m
[1;32m      6[0m [0;32mfor[0m [0mpage[0m [0;32min[0m [0mrange[0m[0;34m([0m[0;36m1[0m[0;34m,[0m[0mnum_of_index_page[0m[0;34m)[0m[0;34m:[0m[0;34m[0m[0;34m[0m[0m
[0;32m----> 7[0;31m     [0mall_links[0m [0;34m=[0m [0mall_links[0m [0;34m+[0m [0mextractArtLinks[0m[0;34m([0m[0murl[0m[0;34m)[0m[0;34m[0m[0;34m[0m[0m
[0m[1;32m      8[0m     [0murl[0m [0;34m=[0m [0mfindPrevIndex[0m[0;34m([0m[0murl[0m[0;34m)[0m[0;34m[0m[0;34m[0m[0m
[1;32m      9[0m [0mlen[0m[0;34m([0m[0mall_links[0m[0;34m)[0m[0;34m[0m[0;34m[0m[0m

[0;32m<ipython-input-1-40f1067daa08>[0m in [0;36mextractArtLinks[0;34m(url)[0m
[1;32m     24[0m                 [0;34m'author'[0m[0;34m:[0m [0mart_meta[0m[0;34m.[0m[0mfind[0m[0;34m([0m[0;34m'div'[0m[0;34m,[0m[0;34m{[0m[0;34m'class'[0m[0;34m:[0m[0;34m'author'[0m[0;34m}[0m[0;34m)[0m[0;34m.[0m[0mget_text[0m[0;34m([0m[0;34m)[0m[0;34m,[0m[0;34m[0m[0;34m[0m[0m
[1;32m     25[0m                 [0;34m'link'[0m[0;34m:[0m [0mart_link[0m[0;34m[[0m[0;34m'href'[0m[0;34m][0m[0;34m,[0m[0;34m[0m[0;34m[0m[0m
[0;32m---> 26[0;31m                 [0;34m'text'[0m[0;34m:[0m [0mextractArtText[0m[0;34m([0m[0;34m'https://www.ptt.cc'[0m [0;34m+[0m [0mart_link[0m[0;34m[[0m[0;34m'href'[0m[0;34m][0m[0;34m)[0m[0;34m[0m[0;34m[0m[0m
[0m[1;32m     27[0m             })
[1;32m     28[0m [0;34m[0m[0m

[0;32m<ipython-input-1-40f1067daa08>[0m in [0;36mextractArtText[0;34m(url)[0m
[1;32m     40[0m [0;31m# extract article contents from  the article hyperlink[0m[0;34m[0m[0;34m[0m[0;34m[0m[0m
[1;32m     41[0m [0;32mdef[0m [0mextractArtText[0m[0;34m([0m[0murl[0m[0;34m)[0m[0;34m:[0m[0;34m[0m[0;34m[0m[0m
[0;32m---> 42[0;31m     [0mr[0m [0;34m=[0m [0mrequests[0m[0;34m.[0m[0mget[0m[0;34m([0m[0murl[0m[0;34m,[0m [0mcookies[0m[0;34m=[0m[0;34m{[0m[0;34m'over18'[0m[0;34m:[0m[0;34m'1'[0m[0;34m}[0m[0;34m)[0m[0;34m[0m[0;34m[0m[0m
[0m[1;32m     43[0m     [0mpage_soup[0m [0;34m=[0m [0msoup[0m[0;34m([0m[0mr[0m[0;34m.[0m[0mtext[0m[0;34m,[0m [0;34m"lxml"[0m[0;34m)[0m[0;34m[0m[0;34m[0m[0m
[1;32m     44[0m     [0;31m#print(page_soup.find("div",{"id":"main-content"}).get_text())[0m[0;34m[0m[0;34m[0m[0;34m[0m[0m

[0;32m~/opt/anaconda3/envs/ckiptagger/lib/python3.6/site-packages/requests/api.py[0m in [0;36mget[0;34m(url, params, **kwargs)[0m
[1;32m     74[0m [0;34m[0m[0m
[1;32m     75[0m     [0mkwargs[0m[0;34m.[0m[0msetdefault[0m[0;34m([0m[0;34m'allow_redirects'[0m[0;34m,[0m [0;32mTrue[0m[0;34m)[0m[0;34m[0m[0;34m[0m[0m
[0;32m---> 76[0;31m     [0;32mreturn[0m [0mrequest[0m[0;34m([0m[0;34m'get'[0m[0;34m,[0m [0murl[0m[0;34m,[0m [0mparams[0m[0;34m=[0m[0mparams[0m[0;34m,[0m [0;34m**[0m[0mkwargs[0m[0;34m)[0m[0;34m[0m[0;34m[0m[0m
[0m[1;32m     77[0m [0;34m[0m[0m
[1;32m     78[0m [0;34m[0m[0m

[0;32m~/opt/anaconda3/envs/ckiptagger/lib/python3.6/site-packages/requests/api.py[0m in [0;36mrequest[0;34m(method, url, **kwargs)[0m
[1;32m     59[0m     [0;31m# cases, and look like a memory leak in others.[0m[0;34m[0m[0;34m[0m[0;34m[0m[0m
[1;32m     60[0m     [0;32mwith[0m [0msessions[0m[0;34m.[0m[0mSession[0m[0;34m([0m[0;34m)[0m [0;32mas[0m [0msession[0m[0;34m:[0m[0;34m[0m[0;34m[0m[0m
[0;32m---> 61[0;31m         [0;32mreturn[0m [0msession[0m[0;34m.[0m[0mrequest[0m[0;34m([0m[0mmethod[0m[0;34m=[0m[0mmethod[0m[0;34m,[0m [0murl[0m[0;34m=[0m[0murl[0m[0;34m,[0m [0;34m**[0m[0mkwargs[0m[0;34m)[0m[0;34m[0m[0;34m[0m[0m
[0m[1;32m     62[0m [0;34m[0m[0m
[1;32m     63[0m [0;34m[0m[0m

[0;32m~/opt/anaconda3/envs/ckiptagger/lib/python3.6/site-packages/requests/sessions.py[0m in [0;36mrequest[0;34m(self, method, url, params, data, headers, cookies, files, auth, timeout, allow_redirects, proxies, hooks, stream, verify, cert, json)[0m
[1;32m    528[0m         }
[1;32m    529[0m         [0msend_kwargs[0m[0;34m.[0m[0mupdate[0m[0;34m([0m[0msettings[0m[0;34m)[0m[0;34m[0m[0;34m[0m[0m
[0;32m--> 530[0;31m         [0mresp[0m [0;34m=[0m [0mself[0m[0;34m.[0m[0msend[0m[0;34m([0m[0mprep[0m[0;34m,[0m [0;34m**[0m[0msend_kwargs[0m[0;34m)[0m[0;34m[0m[0;34m[0m[0m
[0m[1;32m    531[0m [0;34m[0m[0m
[1;32m    532[0m         [0;32mreturn[0m [0mresp[0m[0;34m[0m[0;34m[0m[0m

[0;32m~/opt/anaconda3/envs/ckiptagger/lib/python3.6/site-packages/requests/sessions.py[0m in [0;36msend[0;34m(self, request, **kwargs)[0m
[1;32m    641[0m [0;34m[0m[0m
[1;32m    642[0m         [0;31m# Send the request[0m[0;34m[0m[0;34m[0m[0;34m[0m[0m
[0;32m--> 643[0;31m         [0mr[0m [0;34m=[0m [0madapter[0m[0;34m.[0m[0msend[0m[0;34m([0m[0mrequest[0m[0;34m,[0m [0;34m**[0m[0mkwargs[0m[0;34m)[0m[0;34m[0m[0;34m[0m[0m
[0m[1;32m    644[0m [0;34m[0m[0m
[1;32m    645[0m         [0;31m# Total elapsed time of the request (approximately)[0m[0;34m[0m[0;34m[0m[0;34m[0m[0m

[0;32m~/opt/anaconda3/envs/ckiptagger/lib/python3.6/site-packages/requests/adapters.py[0m in [0;36msend[0;34m(self, request, stream, timeout, verify, cert, proxies)[0m
[1;32m    496[0m [0;34m[0m[0m
[1;32m    497[0m         [0;32mexcept[0m [0;34m([0m[0mProtocolError[0m[0;34m,[0m [0msocket[0m[0;34m.[0m[0merror[0m[0;34m)[0m [0;32mas[0m [0merr[0m[0;34m:[0m[0;34m[0m[0;34m[0m[0m
[0;32m--> 498[0;31m             [0;32mraise[0m [0mConnectionError[0m[0;34m([0m[0merr[0m[0;34m,[0m [0mrequest[0m[0;34m=[0m[0mrequest[0m[0;34m)[0m[0;34m[0m[0;34m[0m[0m
[0m[1;32m    499[0m [0;34m[0m[0m
[1;32m    500[0m         [0;32mexcept[0m [0mMaxRetryError[0m [0;32mas[0m [0me[0m[0;34m:[0m[0;34m[0m[0;34m[0m[0m

[0;31mConnectionError[0m: ('Connection aborted.', RemoteDisconnected('Remote end closed connection without response',))
ConnectionError: ('Connection aborted.', RemoteDisconnected('Remote end closed connection without response',))

