Traceback (most recent call last):
  File "/Users/Alvin/opt/anaconda3/lib/python3.7/site-packages/jupyter_cache/executors/utils.py", line 56, in single_nb_execution
    record_timing=False,
  File "/Users/Alvin/opt/anaconda3/lib/python3.7/site-packages/nbclient/client.py", line 1082, in execute
    return NotebookClient(nb=nb, resources=resources, km=km, **kwargs).execute()
  File "/Users/Alvin/opt/anaconda3/lib/python3.7/site-packages/nbclient/util.py", line 74, in wrapped
    return just_run(coro(*args, **kwargs))
  File "/Users/Alvin/opt/anaconda3/lib/python3.7/site-packages/nbclient/util.py", line 53, in just_run
    return loop.run_until_complete(coro)
  File "/Users/Alvin/opt/anaconda3/lib/python3.7/asyncio/base_events.py", line 583, in run_until_complete
    return future.result()
  File "/Users/Alvin/opt/anaconda3/lib/python3.7/site-packages/nbclient/client.py", line 536, in async_execute
    cell, index, execution_count=self.code_cells_executed + 1
  File "/Users/Alvin/opt/anaconda3/lib/python3.7/site-packages/nbclient/client.py", line 827, in async_execute_cell
    self._check_raise_for_error(cell, exec_reply)
  File "/Users/Alvin/opt/anaconda3/lib/python3.7/site-packages/nbclient/client.py", line 735, in _check_raise_for_error
    raise CellExecutionError.from_cell_and_msg(cell, exec_reply['content'])
nbclient.exceptions.CellExecutionError: An error occurred while executing the following cell:
------------------
model.wv.most_similar(positive=['woman', 'king'], negative=['man'], topn=1)[0]
------------------

[0;31m---------------------------------------------------------------------------[0m
[0;31mNameError[0m                                 Traceback (most recent call last)
[0;32m<ipython-input-4-1aed78d8f4cd>[0m in [0;36m<module>[0;34m[0m
[0;32m----> 1[0;31m [0mmodel[0m[0;34m.[0m[0mwv[0m[0;34m.[0m[0mmost_similar[0m[0;34m([0m[0mpositive[0m[0;34m=[0m[0;34m[[0m[0;34m'woman'[0m[0;34m,[0m [0;34m'king'[0m[0;34m][0m[0;34m,[0m [0mnegative[0m[0;34m=[0m[0;34m[[0m[0;34m'man'[0m[0;34m][0m[0;34m,[0m [0mtopn[0m[0;34m=[0m[0;36m1[0m[0;34m)[0m[0;34m[[0m[0;36m0[0m[0;34m][0m[0;34m[0m[0;34m[0m[0m
[0m
[0;31mNameError[0m: name 'model' is not defined
NameError: name 'model' is not defined

