Traceback (most recent call last):
  File "/Users/Alvin/opt/anaconda3/lib/python3.7/site-packages/jupyter_cache/executors/utils.py", line 56, in single_nb_execution
    record_timing=False,
  File "/Users/Alvin/opt/anaconda3/lib/python3.7/site-packages/nbclient/client.py", line 1082, in execute
    return NotebookClient(nb=nb, resources=resources, km=km, **kwargs).execute()
  File "/Users/Alvin/opt/anaconda3/lib/python3.7/site-packages/nbclient/util.py", line 74, in wrapped
    return just_run(coro(*args, **kwargs))
  File "/Users/Alvin/opt/anaconda3/lib/python3.7/site-packages/nbclient/util.py", line 53, in just_run
    return loop.run_until_complete(coro)
  File "/Users/Alvin/opt/anaconda3/lib/python3.7/asyncio/base_events.py", line 583, in run_until_complete
    return future.result()
  File "/Users/Alvin/opt/anaconda3/lib/python3.7/site-packages/nbclient/client.py", line 536, in async_execute
    cell, index, execution_count=self.code_cells_executed + 1
  File "/Users/Alvin/opt/anaconda3/lib/python3.7/site-packages/nbclient/client.py", line 827, in async_execute_cell
    self._check_raise_for_error(cell, exec_reply)
  File "/Users/Alvin/opt/anaconda3/lib/python3.7/site-packages/nbclient/client.py", line 735, in _check_raise_for_error
    raise CellExecutionError.from_cell_and_msg(cell, exec_reply['content'])
nbclient.exceptions.CellExecutionError: An error occurred while executing the following cell:
------------------
words=[]
classes = []
documents = []
ignore_words = ['?', '!']
data_file = open('../data/intents.json').read()
intents = json.loads(data_file)
------------------

[0;31m---------------------------------------------------------------------------[0m
[0;31mFileNotFoundError[0m                         Traceback (most recent call last)
[0;32m<ipython-input-2-4cb211752198>[0m in [0;36m<module>[0;34m[0m
[1;32m      3[0m [0mdocuments[0m [0;34m=[0m [0;34m[[0m[0;34m][0m[0;34m[0m[0;34m[0m[0m
[1;32m      4[0m [0mignore_words[0m [0;34m=[0m [0;34m[[0m[0;34m'?'[0m[0;34m,[0m [0;34m'!'[0m[0;34m][0m[0;34m[0m[0;34m[0m[0m
[0;32m----> 5[0;31m [0mdata_file[0m [0;34m=[0m [0mopen[0m[0;34m([0m[0;34m'../data/intents.json'[0m[0;34m)[0m[0;34m.[0m[0mread[0m[0;34m([0m[0;34m)[0m[0;34m[0m[0;34m[0m[0m
[0m[1;32m      6[0m [0mintents[0m [0;34m=[0m [0mjson[0m[0;34m.[0m[0mloads[0m[0;34m([0m[0mdata_file[0m[0;34m)[0m[0;34m[0m[0;34m[0m[0m

[0;31mFileNotFoundError[0m: [Errno 2] No such file or directory: '../data/intents.json'
FileNotFoundError: [Errno 2] No such file or directory: '../data/intents.json'

