Traceback (most recent call last):
  File "/Users/alvinchen/opt/anaconda3/lib/python3.7/site-packages/jupyter_cache/executors/utils.py", line 56, in single_nb_execution
    record_timing=False,
  File "/Users/alvinchen/opt/anaconda3/lib/python3.7/site-packages/nbclient/client.py", line 1082, in execute
    return NotebookClient(nb=nb, resources=resources, km=km, **kwargs).execute()
  File "/Users/alvinchen/opt/anaconda3/lib/python3.7/site-packages/nbclient/util.py", line 74, in wrapped
    return just_run(coro(*args, **kwargs))
  File "/Users/alvinchen/opt/anaconda3/lib/python3.7/site-packages/nbclient/util.py", line 53, in just_run
    return loop.run_until_complete(coro)
  File "/Users/alvinchen/opt/anaconda3/lib/python3.7/asyncio/base_events.py", line 583, in run_until_complete
    return future.result()
  File "/Users/alvinchen/opt/anaconda3/lib/python3.7/site-packages/nbclient/client.py", line 536, in async_execute
    cell, index, execution_count=self.code_cells_executed + 1
  File "/Users/alvinchen/opt/anaconda3/lib/python3.7/site-packages/nbclient/client.py", line 827, in async_execute_cell
    self._check_raise_for_error(cell, exec_reply)
  File "/Users/alvinchen/opt/anaconda3/lib/python3.7/site-packages/nbclient/client.py", line 735, in _check_raise_for_error
    raise CellExecutionError.from_cell_and_msg(cell, exec_reply['content'])
nbclient.exceptions.CellExecutionError: An error occurred while executing the following cell:
------------------
## Train both PV-DBOW and PV-DM and combine the two

documents = train_corpus
models[0].build_vocab(documents)
models[1].reset_from(models[0])

for model in models:
   model.train(documents, total_examples=model.corpus_count, epochs=model.epochs)

from gensim.test.test_doc2vec import ConcatenatedDoc2Vec
new_model = ConcatenatedDoc2Vec((models[0], models[1]))
------------------

[0;31m---------------------------------------------------------------------------[0m
[0;31mModuleNotFoundError[0m                       Traceback (most recent call last)
[0;32m<ipython-input-5-67208ae17468>[0m in [0;36m<module>[0;34m[0m
[1;32m      8[0m    [0mmodel[0m[0;34m.[0m[0mtrain[0m[0;34m([0m[0mdocuments[0m[0;34m,[0m [0mtotal_examples[0m[0;34m=[0m[0mmodel[0m[0;34m.[0m[0mcorpus_count[0m[0;34m,[0m [0mepochs[0m[0;34m=[0m[0mmodel[0m[0;34m.[0m[0mepochs[0m[0;34m)[0m[0;34m[0m[0m
[1;32m      9[0m [0;34m[0m[0m
[0;32m---> 10[0;31m [0;32mfrom[0m [0mgensim[0m[0;34m.[0m[0mtest[0m[0;34m.[0m[0mtest_doc2vec[0m [0;32mimport[0m [0mConcatenatedDoc2Vec[0m[0;34m[0m[0m
[0m[1;32m     11[0m [0mnew_model[0m [0;34m=[0m [0mConcatenatedDoc2Vec[0m[0;34m([0m[0;34m([0m[0mmodels[0m[0;34m[[0m[0;36m0[0m[0;34m][0m[0;34m,[0m [0mmodels[0m[0;34m[[0m[0;36m1[0m[0;34m][0m[0;34m)[0m[0;34m)[0m[0;34m[0m[0m

[0;32m~/opt/anaconda3/envs/python-notes/lib/python3.7/site-packages/gensim/test/test_doc2vec.py[0m in [0;36m<module>[0;34m[0m
[1;32m     19[0m [0;32mfrom[0m [0msix[0m[0;34m.[0m[0mmoves[0m [0;32mimport[0m [0mzip[0m[0;34m,[0m [0mrange[0m[0;34m[0m[0m
[1;32m     20[0m [0;32mfrom[0m [0mcollections[0m [0;32mimport[0m [0mnamedtuple[0m[0;34m[0m[0m
[0;32m---> 21[0;31m [0;32mfrom[0m [0mtestfixtures[0m [0;32mimport[0m [0mlog_capture[0m[0;34m[0m[0m
[0m[1;32m     22[0m [0;34m[0m[0m
[1;32m     23[0m [0;32mimport[0m [0mnumpy[0m [0;32mas[0m [0mnp[0m[0;34m[0m[0m

[0;31mModuleNotFoundError[0m: No module named 'testfixtures'
ModuleNotFoundError: No module named 'testfixtures'

