Traceback (most recent call last):
  File "/Users/Alvin/opt/anaconda3/lib/python3.7/site-packages/jupyter_cache/executors/utils.py", line 56, in single_nb_execution
    record_timing=False,
  File "/Users/Alvin/opt/anaconda3/lib/python3.7/site-packages/nbclient/client.py", line 1082, in execute
    return NotebookClient(nb=nb, resources=resources, km=km, **kwargs).execute()
  File "/Users/Alvin/opt/anaconda3/lib/python3.7/site-packages/nbclient/util.py", line 74, in wrapped
    return just_run(coro(*args, **kwargs))
  File "/Users/Alvin/opt/anaconda3/lib/python3.7/site-packages/nbclient/util.py", line 53, in just_run
    return loop.run_until_complete(coro)
  File "/Users/Alvin/opt/anaconda3/lib/python3.7/asyncio/base_events.py", line 583, in run_until_complete
    return future.result()
  File "/Users/Alvin/opt/anaconda3/lib/python3.7/site-packages/nbclient/client.py", line 536, in async_execute
    cell, index, execution_count=self.code_cells_executed + 1
  File "/Users/Alvin/opt/anaconda3/lib/python3.7/site-packages/nbclient/client.py", line 827, in async_execute_cell
    self._check_raise_for_error(cell, exec_reply)
  File "/Users/Alvin/opt/anaconda3/lib/python3.7/site-packages/nbclient/client.py", line 735, in _check_raise_for_error
    raise CellExecutionError.from_cell_and_msg(cell, exec_reply['content'])
nbclient.exceptions.CellExecutionError: An error occurred while executing the following cell:
------------------
# set dictionary

jieba.set_dictionary('../../../Corpus/jiaba/dict.txt.jiebatw.txt/')
#jieba.load_userdict()

text = '據《日經亞洲評論》網站報導，儘管美國總統川普發起了讓美國製造業回歸的貿易戰，但包括電動汽車製造商特斯拉在內的一些公司反而加大馬力在大陸進行生產。另據高盛近日發布的一份報告指出，半導體設備和材料以及醫療保健領域的大多數公司實際上正擴大在大陸的生產，許多美國製造業拒絕「退出中國」。'

print(' '.join(jieba.cut(text, cut_all=False, HMM=True))+'\n')
print(' '.join(jieba.cut(text, cut_all=False, HMM=False))+'\n')
print(' '.join(jieba.cut(text, cut_all=True, HMM=True))+'\n')

text_pos = posseg.cut(text)
#print(type(text_pos))
for word, tag in text_pos:
    print(word+'/'+tag)
------------------

[0;31m---------------------------------------------------------------------------[0m
[0;31mException[0m                                 Traceback (most recent call last)
[0;32m<ipython-input-2-a432c2e1005e>[0m in [0;36m<module>[0;34m[0m
[1;32m      1[0m [0;31m# set dictionary[0m[0;34m[0m[0;34m[0m[0;34m[0m[0m
[1;32m      2[0m [0;34m[0m[0m
[0;32m----> 3[0;31m [0mjieba[0m[0;34m.[0m[0mset_dictionary[0m[0;34m([0m[0;34m'../../../Corpus/jiaba/dict.txt.jiebatw.txt/'[0m[0;34m)[0m[0;34m[0m[0;34m[0m[0m
[0m[1;32m      4[0m [0;31m#jieba.load_userdict()[0m[0;34m[0m[0;34m[0m[0;34m[0m[0m
[1;32m      5[0m [0;34m[0m[0m

[0;32m~/opt/anaconda3/envs/ckiptagger/lib/python3.6/site-packages/jieba/__init__.py[0m in [0;36mset_dictionary[0;34m(self, dictionary_path)[0m
[1;32m    511[0m             [0mabs_path[0m [0;34m=[0m [0m_get_abs_path[0m[0;34m([0m[0mdictionary_path[0m[0;34m)[0m[0;34m[0m[0;34m[0m[0m
[1;32m    512[0m             [0;32mif[0m [0;32mnot[0m [0mos[0m[0;34m.[0m[0mpath[0m[0;34m.[0m[0misfile[0m[0;34m([0m[0mabs_path[0m[0;34m)[0m[0;34m:[0m[0;34m[0m[0;34m[0m[0m
[0;32m--> 513[0;31m                 [0;32mraise[0m [0mException[0m[0;34m([0m[0;34m"jieba: file does not exist: "[0m [0;34m+[0m [0mabs_path[0m[0;34m)[0m[0;34m[0m[0;34m[0m[0m
[0m[1;32m    514[0m             [0mself[0m[0;34m.[0m[0mdictionary[0m [0;34m=[0m [0mabs_path[0m[0;34m[0m[0;34m[0m[0m
[1;32m    515[0m             [0mself[0m[0;34m.[0m[0minitialized[0m [0;34m=[0m [0;32mFalse[0m[0;34m[0m[0;34m[0m[0m

[0;31mException[0m: jieba: file does not exist: /Users/Alvin/Corpus/jiaba/dict.txt.jiebatw.txt
Exception: jieba: file does not exist: /Users/Alvin/Corpus/jiaba/dict.txt.jiebatw.txt

