Traceback (most recent call last):
  File "/Users/Alvin/opt/anaconda3/envs/python-notes/lib/python3.7/site-packages/jupyter_cache/executors/utils.py", line 56, in single_nb_execution
    record_timing=False,
  File "/Users/Alvin/opt/anaconda3/envs/python-notes/lib/python3.7/site-packages/nbclient/client.py", line 1082, in execute
    return NotebookClient(nb=nb, resources=resources, km=km, **kwargs).execute()
  File "/Users/Alvin/opt/anaconda3/envs/python-notes/lib/python3.7/site-packages/nbclient/util.py", line 74, in wrapped
    return just_run(coro(*args, **kwargs))
  File "/Users/Alvin/opt/anaconda3/envs/python-notes/lib/python3.7/site-packages/nbclient/util.py", line 53, in just_run
    return loop.run_until_complete(coro)
  File "/Users/Alvin/opt/anaconda3/envs/python-notes/lib/python3.7/asyncio/base_events.py", line 568, in run_until_complete
    return future.result()
  File "/Users/Alvin/opt/anaconda3/envs/python-notes/lib/python3.7/site-packages/nbclient/client.py", line 536, in async_execute
    cell, index, execution_count=self.code_cells_executed + 1
  File "/Users/Alvin/opt/anaconda3/envs/python-notes/lib/python3.7/site-packages/nbclient/client.py", line 827, in async_execute_cell
    self._check_raise_for_error(cell, exec_reply)
  File "/Users/Alvin/opt/anaconda3/envs/python-notes/lib/python3.7/site-packages/nbclient/client.py", line 735, in _check_raise_for_error
    raise CellExecutionError.from_cell_and_msg(cell, exec_reply['content'])
nbclient.exceptions.CellExecutionError: An error occurred while executing the following cell:
------------------
# model.save('../data/sent-analysis-lstm-v1.h5')
import keras
model = keras.models.load_model('../data/sent-analysis-lstm-v1.h5')
------------------

[0;31m---------------------------------------------------------------------------[0m
[0;31mOSError[0m                                   Traceback (most recent call last)
[0;32m<ipython-input-11-d46bb94b5e08>[0m in [0;36m<module>[0;34m[0m
[1;32m      1[0m [0;31m# model.save('../data/sent-analysis-lstm-v1.h5')[0m[0;34m[0m[0;34m[0m[0;34m[0m[0m
[1;32m      2[0m [0;32mimport[0m [0mkeras[0m[0;34m[0m[0;34m[0m[0m
[0;32m----> 3[0;31m [0mmodel[0m [0;34m=[0m [0mkeras[0m[0;34m.[0m[0mmodels[0m[0;34m.[0m[0mload_model[0m[0;34m([0m[0;34m'../data/sent-analysis-lstm-v1.h5'[0m[0;34m)[0m[0;34m[0m[0;34m[0m[0m
[0m
[0;32m~/opt/anaconda3/lib/python3.7/site-packages/tensorflow/python/keras/saving/save.py[0m in [0;36mload_model[0;34m(filepath, custom_objects, compile, options)[0m
[1;32m    184[0m     [0mfilepath[0m [0;34m=[0m [0mpath_to_string[0m[0;34m([0m[0mfilepath[0m[0;34m)[0m[0;34m[0m[0;34m[0m[0m
[1;32m    185[0m     [0;32mif[0m [0misinstance[0m[0;34m([0m[0mfilepath[0m[0;34m,[0m [0msix[0m[0;34m.[0m[0mstring_types[0m[0;34m)[0m[0;34m:[0m[0;34m[0m[0;34m[0m[0m
[0;32m--> 186[0;31m       [0mloader_impl[0m[0;34m.[0m[0mparse_saved_model[0m[0;34m([0m[0mfilepath[0m[0;34m)[0m[0;34m[0m[0;34m[0m[0m
[0m[1;32m    187[0m       [0;32mreturn[0m [0msaved_model_load[0m[0;34m.[0m[0mload[0m[0;34m([0m[0mfilepath[0m[0;34m,[0m [0mcompile[0m[0;34m,[0m [0moptions[0m[0;34m)[0m[0;34m[0m[0;34m[0m[0m
[1;32m    188[0m [0;34m[0m[0m

[0;32m~/opt/anaconda3/lib/python3.7/site-packages/tensorflow/python/saved_model/loader_impl.py[0m in [0;36mparse_saved_model[0;34m(export_dir)[0m
[1;32m    111[0m                   (export_dir,
[1;32m    112[0m                    [0mconstants[0m[0;34m.[0m[0mSAVED_MODEL_FILENAME_PBTXT[0m[0;34m,[0m[0;34m[0m[0;34m[0m[0m
[0;32m--> 113[0;31m                    constants.SAVED_MODEL_FILENAME_PB))
[0m[1;32m    114[0m [0;34m[0m[0m
[1;32m    115[0m [0;34m[0m[0m

[0;31mOSError[0m: SavedModel file does not exist at: ../data/sent-analysis-lstm-v1.h5/{saved_model.pbtxt|saved_model.pb}
OSError: SavedModel file does not exist at: ../data/sent-analysis-lstm-v1.h5/{saved_model.pbtxt|saved_model.pb}

