Traceback (most recent call last):
  File "/Users/Alvin/opt/anaconda3/envs/python-notes/lib/python3.7/site-packages/jupyter_cache/executors/utils.py", line 56, in single_nb_execution
    record_timing=False,
  File "/Users/Alvin/opt/anaconda3/envs/python-notes/lib/python3.7/site-packages/nbclient/client.py", line 1082, in execute
    return NotebookClient(nb=nb, resources=resources, km=km, **kwargs).execute()
  File "/Users/Alvin/opt/anaconda3/envs/python-notes/lib/python3.7/site-packages/nbclient/util.py", line 74, in wrapped
    return just_run(coro(*args, **kwargs))
  File "/Users/Alvin/opt/anaconda3/envs/python-notes/lib/python3.7/site-packages/nbclient/util.py", line 53, in just_run
    return loop.run_until_complete(coro)
  File "/Users/Alvin/opt/anaconda3/envs/python-notes/lib/python3.7/asyncio/base_events.py", line 568, in run_until_complete
    return future.result()
  File "/Users/Alvin/opt/anaconda3/envs/python-notes/lib/python3.7/site-packages/nbclient/client.py", line 536, in async_execute
    cell, index, execution_count=self.code_cells_executed + 1
  File "/Users/Alvin/opt/anaconda3/envs/python-notes/lib/python3.7/site-packages/nbclient/client.py", line 827, in async_execute_cell
    self._check_raise_for_error(cell, exec_reply)
  File "/Users/Alvin/opt/anaconda3/envs/python-notes/lib/python3.7/site-packages/nbclient/client.py", line 735, in _check_raise_for_error
    raise CellExecutionError.from_cell_and_msg(cell, exec_reply['content'])
nbclient.exceptions.CellExecutionError: An error occurred while executing the following cell:
------------------
import seaborn as sns
import pandas as pd
import pickle
%matplotlib inline

## load previous saved df
pickle_in = open("../data/text-gen-lstm-nietzschet-history.pickle","rb")
hist_df = pickle.load(pickle_in)

#hist_df=pd.DataFrame(list(zip(epochs, loss_values)), columns=['epochs','loss_values'])
sns.set(style='darkgrid')
sns.relplot(data=hist_df,x='epochs', y='loss_values', kind='line')
------------------

[0;31m---------------------------------------------------------------------------[0m
[0;31mFileNotFoundError[0m                         Traceback (most recent call last)
[0;32m<ipython-input-11-9a7d09c06d91>[0m in [0;36m<module>[0;34m[0m
[1;32m      5[0m [0;34m[0m[0m
[1;32m      6[0m [0;31m## load previous saved df[0m[0;34m[0m[0;34m[0m[0;34m[0m[0m
[0;32m----> 7[0;31m [0mpickle_in[0m [0;34m=[0m [0mopen[0m[0;34m([0m[0;34m"../data/text-gen-lstm-nietzschet-history.pickle"[0m[0;34m,[0m[0;34m"rb"[0m[0;34m)[0m[0;34m[0m[0;34m[0m[0m
[0m[1;32m      8[0m [0mhist_df[0m [0;34m=[0m [0mpickle[0m[0;34m.[0m[0mload[0m[0;34m([0m[0mpickle_in[0m[0;34m)[0m[0;34m[0m[0;34m[0m[0m
[1;32m      9[0m [0;34m[0m[0m

[0;31mFileNotFoundError[0m: [Errno 2] No such file or directory: '../data/text-gen-lstm-nietzschet-history.pickle'
FileNotFoundError: [Errno 2] No such file or directory: '../data/text-gen-lstm-nietzschet-history.pickle'

